<?xml version='1.0' encoding='utf-8'?>
<mujoco model="dual_ur5_shadow">
  <compiler angle="radian" meshdir="./"/>

  <option impratio="10" cone="elliptic" />

  <visual>
    <global azimuth="120" elevation="-20" />
    <headlight diffuse="0.6 0.6 0.6" specular="0 0 0" />
    <rgba haze="0.15 0.25 0.35 1" />
  </visual>

  <asset>
    <texture type="skybox"  builtin="gradient" rgb1="1 1 1" rgb2="1 1 1" width="512" height="3072" />
    <texture type="2d" name="groundplane" builtin="checker" mark="edge" rgb1="0.2 0.3 0.4" rgb2="0.1 0.2 0.3" markrgb="0.8 0.8 0.8" width="300" height="300" />
    <material name="gray" class="ur5" rgba="0.6 0.6 0.6 1" />
    <material name="jointgray" class="ur5" rgba="0.278 0.278 0.278 1" />
    <material name="linkgray" class="ur5" rgba="0.82 0.82 0.82 1" />
    <material name="urblue" class="ur5" rgba="0.49 0.678 0.8 1" />
    <material name="black" shininess="0.25" rgba="0.16355 0.16355 0.16355 1" />
    <material name="metallic" specular="0" shininess="0.25" rgba="0.9 0.9 0.9 1" />
    <material name="groundplane" texture="groundplane" texuniform="true" texrepeat="5 5" reflectance="0.2" />
    <mesh name="dual_base" content_type="model/stl" file="dual_ur5/dual_base.STL" />
    <mesh name="base" content_type="model/stl" file="dual_ur5/ur5/visual/base.stl" />
    <mesh name="shoulder" content_type="model/stl" file="dual_ur5/ur5/visual/shoulder.stl" />
    <mesh name="upperarm" content_type="model/stl" file="dual_ur5/ur5/visual/upperarm.stl" />
    <mesh name="forearm" content_type="model/stl" file="dual_ur5/ur5/visual/forearm.stl" />
    <mesh name="wrist1" content_type="model/stl" file="dual_ur5/ur5/visual/wrist1.stl" />
    <mesh name="wrist2" content_type="model/stl" file="dual_ur5/ur5/visual/wrist2.stl" />
    <mesh name="wrist3" content_type="model/stl" file="dual_ur5/ur5/visual/wrist3.stl" />
    <mesh name="rh_palm" class="right_hand" content_type="model/obj" file="shadow/palm.obj" />
    <mesh name="rh_f_knuckle" class="right_hand" content_type="model/obj" file="shadow/f_knuckle.obj" />
    <mesh name="rh_f_proximal" class="right_hand" content_type="model/obj" file="shadow/f_proximal.obj" />
    <mesh name="rh_f_middle" class="right_hand" content_type="model/obj" file="shadow/f_middle.obj" />
    <mesh name="rh_f_distal" class="right_hand" content_type="model/obj" file="shadow/f_distal_pst_cut_sm.obj" />
    <mesh name="rh_lf_metacarpal" class="right_hand" content_type="model/obj" file="shadow/lf_metacarpal.obj" />
    <mesh name="rh_th_proximal" class="right_hand" content_type="model/obj" file="shadow/th_proximal.obj" />
    <mesh name="rh_th_middle" class="right_hand" content_type="model/obj" file="shadow/th_middle.obj" />
    <mesh name="rh_th_distal" class="right_hand" content_type="model/obj" file="shadow/th_distal_pst_cut_sm.obj" />
    <mesh name="lh_palm" class="left_hand" content_type="model/obj" file="shadow/palm.obj" scale="-0.001 0.001 0.001" />
    <mesh name="lh_f_knuckle" class="left_hand" file="shadow/f_knuckle.obj" />
    <mesh name="lh_f_proximal" class="left_hand" file="shadow/f_proximal.obj" />
    <mesh name="lh_f_middle" class="left_hand" file="shadow/f_middle.obj" />
    <mesh name="lh_f_distal" class="left_hand" file="shadow/f_distal_pst_cut_sm.obj" />
    <mesh name="lh_lf_metacarpal" class="left_hand" content_type="model/obj" file="shadow/lf_metacarpal.obj" scale="-0.001 0.001 0.001" />
    <mesh name="lh_th_proximal" class="left_hand" file="shadow/th_proximal.obj" />
    <mesh name="lh_th_middle" class="left_hand" file="shadow/th_middle.obj" />
    <mesh name="lh_th_distal" class="left_hand" file="shadow/th_distal_pst_cut_sm.obj" />
  </asset>

  <worldbody>
    <light pos="0 0 1" dir="0 0 -1" />
    <light pos="0.3 0 1.5" dir="0 0 -1"/>
    <body name="base" gravcomp="1">
      <body name="dual_base" gravcomp="1">
        <geom class="visual" type="mesh" material="linkgray" mesh="dual_base" />
        <geom class="collision" size="0.045 0.35 0.045" type="box" rgba="0.6 0.6 0.6 1" />
        <geom class="collision" size="0.06 0.06 0.75" pos="0 0 -0.6" type="box" rgba="0.6 0.6 0.6 1" />
        <geom class="collision" size="0.01 0.2 0.13" pos="0 0 -0.13" type="box" rgba="0.6 0.6 0.6 1" />
        <body name="ra_base_link" pos="0 -0.357 0" quat="0.707107 0.707107 0 0" gravcomp="1">
          <body name="ra_base_link_inertia" quat="0 0 0 1" gravcomp="1">
            <inertial pos="0 0 0" quat="0.5 0.5 -0.5 0.5" mass="4" diaginertia="0.0072 0.00443333 0.00443333" />
            <geom class="visual" quat="0 0 0 1" type="mesh" material="gray" mesh="base" />
            <body name="ra_shoulder_link" pos="0 0 0.089159" gravcomp="1">
              <inertial pos="0 -0.00193 -0.02561" mass="3.7" diaginertia="0.0149724 0.0149724 0.0104063" />
              <joint name="ra_shoulder_pan_joint" class="ur5" pos="0 0 0" axis="0 0 1" actuatorfrcrange="-150 150" />
              <geom class="visual" quat="0 0 0 1" type="mesh" material="gray" mesh="shoulder" />
              <geom name="ra_shoulder_link_geom_0" class="collision" size="0.06 0.06" pos="0 0 -0.04" type="capsule" rgba="1 0 0 1" />
              <body name="ra_upper_arm_link" quat="0.707107 0.707107 0 0" gravcomp="1">
                <inertial pos="-0.2125 0 0.11336" mass="8.393" diaginertia="0.133886 0.133886 0.0151074" />
                <joint name="ra_shoulder_lift_joint" class="ur5" pos="0 0 0" axis="0 0 1" actuatorfrcrange="-150 150" />
                <geom class="visual" pos="0 0 0.13585" quat="0.5 0.5 -0.5 -0.5" type="mesh" material="gray" mesh="upperarm" />
                <geom name="ra_upper_arm_link_geom_1" class="collision" size="0.05 0.2" pos="-0.2 0 0.138" quat="0.5 0.5 -0.5 -0.5" type="capsule" rgba="1 0 0 1" />
                <geom name="ra_upper_arm_link_geom_0" class="collision" size="0.06 0.06" pos="0 0 0.1" quat="0 0.707107 -0.707107 0" type="capsule" rgba="1 0 0 1" />
                <body name="ra_forearm_link" pos="-0.425 0 0" gravcomp="1">
                  <inertial pos="-0.24225 0 0.0265" mass="2.33" diaginertia="0.0312168 0.0312168 0.004095" />
                  <joint name="ra_elbow_joint" class="ur5" pos="0 0 0" axis="0 0 1" range="-3.14159 3.14159" actuatorfrcrange="-150 150" />
                  <geom class="visual" pos="0 0 0.0165" quat="0.5 0.5 -0.5 -0.5" type="mesh" material="gray" mesh="forearm" />
                  <geom name="ra_forearm_link_geom_1" class="collision" size="0.038 0.19" pos="-0.2 0 0.02" quat="0.707107 0 0.707107 0" type="capsule" rgba="1 0 0 1" />
                  <geom name="ra_forearm_link_geom_0" class="collision" size="0.055 0.06" pos="0 0 0.08" type="capsule" rgba="1 0 0 1" />
                  <body name="ra_wrist_1_link" pos="-0.39225 0 0.10915" gravcomp="1">
                    <inertial pos="0 -0.01634 -0.0018" quat="0.5 0.5 -0.5 0.5" mass="1.219" diaginertia="0.0021942 0.00201389 0.00201389" />
                    <joint name="ra_wrist_1_joint" class="ur5" pos="0 0 0" axis="0 0 1" actuatorfrcrange="-28 28" />
                    <geom class="visual" pos="0 0 -0.093" quat="0.707107 0.707107 0 0" type="mesh" material="gray" mesh="wrist1" />
                    <geom name="ra_wrist_1_link_geom_0" class="collision" size="0.04 0.06" pos="0 0 -0.06" type="capsule" rgba="1 0 0 1" />
                    <body name="ra_wrist_2_link" pos="0 -0.09465 -1.9413e-11" quat="0.707107 0.707107 0 0" gravcomp="1">
                      <inertial pos="0 0.01634 -0.0018" quat="0.5 0.5 -0.5 0.5" mass="1.219" diaginertia="0.0021942 0.00183104 0.00183104" />
                      <joint name="ra_wrist_2_joint" class="ur5" pos="0 0 0" axis="0 0 1" actuatorfrcrange="-28 28" />
                      <geom class="visual" pos="0 0 -0.095" quat="1 0 0 0" type="mesh" material="gray" mesh="wrist2" />
                      <geom name="ra_wrist_2_link_geom_1" class="collision" size="0.04 0.035" pos="0 0.01 0" quat="0.707107 0.707107 0 0" type="capsule" rgba="1 0 0 1" />
                      <geom name="ra_wrist_2_link_geom_0" class="collision" size="0.04 0.06" pos="0 0 -0.06" type="capsule" rgba="1 0 0 1" />
                      <body name="ra_wrist_3_link" pos="0 0.0823 -1.688e-11" quat="0.707107 -0.707107 0 0" gravcomp="1">
                        <inertial pos="0 0 -0.001159" quat="0.5 0.5 -0.5 0.5" mass="0.1879" diaginertia="0.000132117 8.06248e-05 8.06248e-05" />
                        <joint name="ra_wrist_3_joint" class="ur5" pos="0 0 0" axis="0 0 1" actuatorfrcrange="-28 28" />
                        <geom class="visual" pos="0 0 -0.0818" quat="0.707107 0.707107 0 0" type="mesh" material="gray" mesh="wrist3" />
                        <body name="ra_ft_frame" quat="0 1 0 0" gravcomp="1" />
                        <body name="ra_flange" quat="0.5 -0.5 -0.5 -0.5" gravcomp="1">
                          <body name="ra_tool0" quat="0.5 0.5 0.5 0.5" gravcomp="1">
                            <body name="rh_palm" pos="0 0 0.034" gravcomp="1">
                              <inertial pos="0 0 0.035" quat="0.707107 0 0 0.707107" mass="0.3" diaginertia="0.0005287 0.0003581 0.000191" />
                              <geom class="rh_plastic_visual" mesh="rh_palm" />
                              <geom class="rh_plastic_collision" size="0.031 0.0035 0.049" pos="0.011 0.0085 0.038" type="box" />
                              <geom class="rh_plastic_collision" size="0.018 0.0085 0.049" pos="-0.002 -0.0035 0.038" type="box" />
                              <geom class="rh_plastic_collision" size="0.013 0.0085 0.005" pos="0.029 -0.0035 0.082" type="box" />
                              <geom class="rh_plastic_collision" size="0.013 0.007 0.009" pos="0.0265 -0.001 0.07" quat="0.987241 0.0990545 0.0124467 0.124052" type="box" />
                              <geom class="rh_plastic_collision" size="0.0105 0.0135 0.012" pos="0.0315 -0.0085 0.001" type="box" />
                              <geom class="rh_plastic_collision" size="0.011 0.0025 0.015" pos="0.0125 -0.015 0.004" quat="0.971338 0 0 -0.237703" type="box" />
                              <geom class="rh_plastic_collision" size="0.009 0.012 0.002" pos="0.011 0 0.089" type="box" />
                              <geom class="rh_plastic_collision" size="0.01 0.012 0.02" pos="-0.03 0 0.009" type="box" />
                              <site name="grasp_site" pos="0 -0.035 0.09" group="4" />
                              <body name="rh_ffknuckle" pos="0.033 0 0.095" gravcomp="1">
                                <inertial pos="0 0 0" quat="0.5 0.5 -0.5 0.5" mass="0.008" diaginertia="3.2e-07 2.6e-07 2.6e-07" />
                                <joint name="rh_FFJ4" class="rh_knuckle" pos="0 0 0" axis="0 -1 0" />
                                <geom class="rh_plastic_visual" pos="0 0 0.0005" material="metallic" mesh="rh_f_knuckle" />
                                <body name="rh_ffproximal" gravcomp="1">
                                  <inertial pos="0 0 0.0225" quat="0.707107 0 0 0.707107" mass="0.03" diaginertia="1e-05 9.8e-06 1.8e-06" />
                                  <joint name="rh_FFJ3" class="rh_proximal" pos="0 0 0" axis="1 0 0" />
                                  <geom class="rh_plastic_visual" mesh="rh_f_proximal" />
                                  <geom class="rh_plastic_collision" size="0.009 0.02" pos="0 0 0.025" type="capsule" />
                                  <body name="rh_ffmiddle" pos="0 0 0.045" gravcomp="1">
                                    <inertial pos="0 0 0.0125" quat="0.707107 0 0 0.707107" mass="0.017" diaginertia="2.7e-06 2.6e-06 8.7e-07" />
                                    <joint name="rh_FFJ2" class="rh_middle_distal" pos="0 0 0" axis="1 0 0" />
                                    <geom class="rh_plastic_visual" mesh="rh_f_middle" />
                                    <geom class="rh_plastic_collision" size="0.009 0.0125" pos="0 0 0.0125" type="capsule" />
                                    <body name="rh_ffdistal" pos="0 0 0.025" gravcomp="1">
                                      <inertial pos="0 0 0.0130769" quat="0.707107 0 0 0.707107" mass="0.013" diaginertia="1.28092e-06 1.12092e-06 5.3e-07" />
                                      <joint name="rh_FFJ1" class="rh_middle_distal" pos="0 0 0" axis="1 0 0" />
                                      <geom class="rh_plastic_visual" mesh="rh_f_distal" />
                                      <geom class="rh_plastic_collision" type="mesh" mesh="rh_f_distal" />
                                    </body>
                                  </body>
                                </body>
                              </body>
                              <body name="rh_mfknuckle" pos="0.011 0 0.099" gravcomp="1">
                                <inertial pos="0 0 0" quat="0.5 0.5 -0.5 0.5" mass="0.008" diaginertia="3.2e-07 2.6e-07 2.6e-07" />
                                <joint name="rh_MFJ4" class="rh_knuckle" pos="0 0 0" axis="0 -1 0" />
                                <geom class="rh_plastic_visual" pos="0 0 0.0005" material="metallic" mesh="rh_f_knuckle" />
                                <body name="rh_mfproximal" gravcomp="1">
                                  <inertial pos="0 0 0.0225" quat="0.707107 0 0 0.707107" mass="0.03" diaginertia="1e-05 9.8e-06 1.8e-06" />
                                  <joint name="rh_MFJ3" class="rh_proximal" pos="0 0 0" axis="1 0 0" />
                                  <geom class="rh_plastic_visual" mesh="rh_f_proximal" />
                                  <geom class="rh_plastic_collision" size="0.009 0.02" pos="0 0 0.025" type="capsule" />
                                  <body name="rh_mfmiddle" pos="0 0 0.045" gravcomp="1">
                                    <inertial pos="0 0 0.0125" quat="0.707107 0 0 0.707107" mass="0.017" diaginertia="2.7e-06 2.6e-06 8.7e-07" />
                                    <joint name="rh_MFJ2" class="rh_middle_distal" pos="0 0 0" axis="1 0 0" />
                                    <geom class="rh_plastic_visual" mesh="rh_f_middle" />
                                    <geom class="rh_plastic_collision" size="0.009 0.0125" pos="0 0 0.0125" type="capsule" />
                                    <body name="rh_mfdistal" pos="0 0 0.025" gravcomp="1">
                                      <inertial pos="0 0 0.0130769" quat="0.707107 0 0 0.707107" mass="0.013" diaginertia="1.28092e-06 1.12092e-06 5.3e-07" />
                                      <joint name="rh_MFJ1" class="rh_middle_distal" pos="0 0 0" axis="1 0 0" />
                                      <geom class="rh_plastic_visual" mesh="rh_f_distal" />
                                      <geom class="rh_plastic_collision" type="mesh" mesh="rh_f_distal" />
                                    </body>
                                  </body>
                                </body>
                              </body>
                              <body name="rh_rfknuckle" pos="-0.011 0 0.095" gravcomp="1">
                                <inertial pos="0 0 0" quat="0.5 0.5 -0.5 0.5" mass="0.008" diaginertia="3.2e-07 2.6e-07 2.6e-07" />
                                <joint name="rh_RFJ4" class="rh_knuckle" pos="0 0 0" axis="0 1 0" />
                                <geom class="rh_plastic_visual" pos="0 0 0.0005" material="metallic" mesh="rh_f_knuckle" />
                                <body name="rh_rfproximal" gravcomp="1">
                                  <inertial pos="0 0 0.0225" quat="0.707107 0 0 0.707107" mass="0.03" diaginertia="1e-05 9.8e-06 1.8e-06" />
                                  <joint name="rh_RFJ3" class="rh_proximal" pos="0 0 0" axis="1 0 0" />
                                  <geom class="rh_plastic_visual" mesh="rh_f_proximal" />
                                  <geom class="rh_plastic_collision" size="0.009 0.02" pos="0 0 0.025" type="capsule" />
                                  <body name="rh_rfmiddle" pos="0 0 0.045" gravcomp="1">
                                    <inertial pos="0 0 0.0125" quat="0.707107 0 0 0.707107" mass="0.017" diaginertia="2.7e-06 2.6e-06 8.7e-07" />
                                    <joint name="rh_RFJ2" class="rh_middle_distal" pos="0 0 0" axis="1 0 0" />
                                    <geom class="rh_plastic_visual" mesh="rh_f_middle" />
                                    <geom class="rh_plastic_collision" size="0.009 0.0125" pos="0 0 0.0125" type="capsule" />
                                    <body name="rh_rfdistal" pos="0 0 0.025" gravcomp="1">
                                      <inertial pos="0 0 0.0130769" quat="0.707107 0 0 0.707107" mass="0.013" diaginertia="1.28092e-06 1.12092e-06 5.3e-07" />
                                      <joint name="rh_RFJ1" class="rh_middle_distal" pos="0 0 0" axis="1 0 0" />
                                      <geom class="rh_plastic_visual" mesh="rh_f_distal" />
                                      <geom class="rh_plastic_collision" type="mesh" mesh="rh_f_distal" />
                                    </body>
                                  </body>
                                </body>
                              </body>
                              <body name="rh_lfmetacarpal" pos="-0.033 0 0.02071" gravcomp="1">
                                <inertial pos="0 0 0.04" quat="0.707107 0 0 0.707107" mass="0.03" diaginertia="1.638e-05 1.45e-05 4.272e-06" />
                                <joint name="rh_LFJ5" class="rh_metacarpal" pos="0 0 0" axis="0.573576 0 0.819152" />
                                <geom class="rh_plastic_visual" mesh="rh_lf_metacarpal" />
                                <geom class="rh_plastic_collision" size="0.011 0.012 0.025" pos="0.002 0 0.033" type="box" />
                                <body name="rh_lfknuckle" pos="0 0 0.06579" gravcomp="1">
                                  <inertial pos="0 0 0" quat="0.5 0.5 -0.5 0.5" mass="0.008" diaginertia="3.2e-07 2.6e-07 2.6e-07" />
                                  <joint name="rh_LFJ4" class="rh_knuckle" pos="0 0 0" axis="0 1 0" />
                                  <geom class="rh_plastic_visual" pos="0 0 0.0005" material="metallic" mesh="rh_f_knuckle" />
                                  <body name="rh_lfproximal" gravcomp="1">
                                    <inertial pos="0 0 0.0225" quat="0.707107 0 0 0.707107" mass="0.03" diaginertia="1e-05 9.8e-06 1.8e-06" />
                                    <joint name="rh_LFJ3" class="rh_proximal" pos="0 0 0" axis="1 0 0" />
                                    <geom class="rh_plastic_visual" mesh="rh_f_proximal" />
                                    <geom class="rh_plastic_collision" size="0.009 0.02" pos="0 0 0.025" type="capsule" />
                                    <body name="rh_lfmiddle" pos="0 0 0.045" gravcomp="1">
                                      <inertial pos="0 0 0.0125" quat="0.707107 0 0 0.707107" mass="0.017" diaginertia="2.7e-06 2.6e-06 8.7e-07" />
                                      <joint name="rh_LFJ2" class="rh_middle_distal" pos="0 0 0" axis="1 0 0" />
                                      <geom class="rh_plastic_visual" mesh="rh_f_middle" />
                                      <geom class="rh_plastic_collision" size="0.009 0.0125" pos="0 0 0.0125" type="capsule" />
                                      <body name="rh_lfdistal" pos="0 0 0.025" gravcomp="1">
                                        <inertial pos="0 0 0.0130769" quat="0.707107 0 0 0.707107" mass="0.013" diaginertia="1.28092e-06 1.12092e-06 5.3e-07" />
                                        <joint name="rh_LFJ1" class="rh_middle_distal" pos="0 0 0" axis="1 0 0" />
                                        <geom class="rh_plastic_visual" mesh="rh_f_distal" />
                                        <geom class="rh_plastic_collision" type="mesh" mesh="rh_f_distal" />
                                      </body>
                                    </body>
                                  </body>
                                </body>
                              </body>
                              <body name="rh_thbase" pos="0.034 -0.00858 0.029" quat="0.92388 0 0.382683 0" gravcomp="1">
                                <inertial pos="0 0 0" mass="0.01" diaginertia="1.6e-07 1.6e-07 1.6e-07" />
                                <joint name="rh_THJ5" class="rh_thbase" pos="0 0 0" axis="0 0 -1" />
                                <geom class="rh_plastic_collision" size="0.013" />
                                <body name="rh_thproximal" gravcomp="1">
                                  <inertial pos="0 0 0.019" mass="0.04" diaginertia="1.36e-05 1.36e-05 3.13e-06" />
                                  <joint name="rh_THJ4" class="rh_thproximal" pos="0 0 0" axis="1 0 0" />
                                  <geom class="rh_plastic_visual" mesh="rh_th_proximal" />
                                  <geom class="rh_plastic_collision" size="0.0105 0.009" pos="0 0 0.02" type="capsule" />
                                  <body name="rh_thhub" pos="0 0 0.038" gravcomp="1">
                                    <inertial pos="0 0 0" mass="0.005" diaginertia="1e-06 1e-06 3e-07" />
                                    <joint name="rh_THJ3" class="rh_thhub" pos="0 0 0" axis="1 0 0" />
                                    <geom class="rh_plastic_collision" size="0.011" />
                                    <body name="rh_thmiddle" gravcomp="1">
                                      <inertial pos="0 0 0.016" mass="0.02" diaginertia="5.1e-06 5.1e-06 1.21e-06" />
                                      <joint name="rh_THJ2" class="rh_thmiddle" pos="0 0 0" axis="0 -1 0" />
                                      <geom class="rh_plastic_visual" mesh="rh_th_middle" />
                                      <geom class="rh_plastic_collision" size="0.009 0.009" pos="0 0 0.012" type="capsule" />
                                      <geom class="rh_plastic_collision" size="0.01" pos="0 0 0.03" />
                                      <body name="rh_thdistal" pos="0 0 0.032" quat="0.707107 0 0 -0.707107" gravcomp="1">
                                        <inertial pos="0 0 0.0145588" quat="0.707107 0 0 0.707107" mass="0.017" diaginertia="2.37794e-06 2.27794e-06 1e-06" />
                                        <joint name="rh_THJ1" class="rh_thdistal" pos="0 0 0" axis="1 0 0" />
                                        <geom class="rh_plastic_visual" mesh="rh_th_distal" />
                                        <geom class="rh_plastic_collision" type="mesh" mesh="rh_th_distal" />
                                      </body>
                                    </body>
                                  </body>
                                </body>
                              </body>
                            </body>
                          </body>
                        </body>
                      </body>
                    </body>
                  </body>
                </body>
              </body>
            </body>
          </body>
          <body name="ra_base" quat="0 0 0 1" gravcomp="1" />
        </body>
        <body name="la_base_link" pos="0 0.357 0" quat="0 0 0.707107 0.707107" gravcomp="1">
          <body name="la_base_link_inertia" quat="0 0 0 1" gravcomp="1">
            <inertial pos="0 0 0" quat="0.5 0.5 -0.5 0.5" mass="4" diaginertia="0.0072 0.00443333 0.00443333" />
            <geom class="visual" quat="0 0 0 1" type="mesh" material="gray" mesh="base" />
            <body name="la_shoulder_link" pos="0 0 0.089159" gravcomp="1">
              <inertial pos="0 -0.00193 -0.02561" mass="3.7" diaginertia="0.0149724 0.0149724 0.0104063" />
              <joint name="la_shoulder_pan_joint" class="ur5" pos="0 0 0" axis="0 0 1" actuatorfrcrange="-150 150" />
              <geom class="visual" quat="0 0 0 1" type="mesh" material="gray" mesh="shoulder" />
              <geom name="la_shoulder_link_geom_0" class="collision" size="0.06 0.06" pos="0 0 -0.04" type="capsule" rgba="1 0 0 1" />
              <body name="la_upper_arm_link" quat="0.707107 0.707107 0 0" gravcomp="1">
                <inertial pos="-0.2125 0 0.11336" mass="8.393" diaginertia="0.133886 0.133886 0.0151074" />
                <joint name="la_shoulder_lift_joint" class="ur5" pos="0 0 0" axis="0 0 1" actuatorfrcrange="-150 150" />
                <geom class="visual" pos="0 0 0.13585" quat="0.5 0.5 -0.5 -0.5" type="mesh" material="gray" mesh="upperarm" />
                <geom name="la_upper_arm_link_geom_1" class="collision" size="0.05 0.2" pos="-0.2 0 0.138" quat="0.5 0.5 -0.5 -0.5" type="capsule" rgba="1 0 0 1" />
                <geom name="la_upper_arm_link_geom_0" class="collision" size="0.06 0.06" pos="0 0 0.1" quat="0 0.707107 -0.707107 0" type="capsule" rgba="1 0 0 1" />
                <body name="la_forearm_link" pos="-0.425 0 0" gravcomp="1">
                  <inertial pos="-0.24225 0 0.0265" mass="2.33" diaginertia="0.0312168 0.0312168 0.004095" />
                  <joint name="la_elbow_joint" class="ur5" pos="0 0 0" axis="0 0 1" range="-3.14159 3.14159" actuatorfrcrange="-150 150" />
                  <geom class="visual" pos="0 0 0.0165" quat="0.5 0.5 -0.5 -0.5" type="mesh" material="gray" mesh="forearm" />
                  <geom name="la_forearm_link_geom_1" class="collision" size="0.038 0.19" pos="-0.2 0 0.02" quat="0.707107 0 0.707107 0" type="capsule" rgba="1 0 0 1" />
                  <geom name="la_forearm_link_geom_0" class="collision" size="0.055 0.06" pos="0 0 0.08" type="capsule" rgba="1 0 0 1" />
                  <body name="la_wrist_1_link" pos="-0.39225 0 0.10915" gravcomp="1">
                    <inertial pos="0 -0.01634 -0.0018" quat="0.5 0.5 -0.5 0.5" mass="1.219" diaginertia="0.0021942 0.00201389 0.00201389" />
                    <joint name="la_wrist_1_joint" class="ur5" pos="0 0 0" axis="0 0 1" actuatorfrcrange="-28 28" />
                    <geom class="visual" pos="0 0 -0.093" quat="0.707107 0.707107 0 0" type="mesh" material="gray" mesh="wrist1" />
                    <geom name="la_wrist_1_link_geom_0" class="collision" size="0.04 0.06" pos="0 0 -0.06" type="capsule" rgba="1 0 0 1" />
                    <body name="la_wrist_2_link" pos="0 -0.09465 -1.9413e-11" quat="0.707107 0.707107 0 0" gravcomp="1">
                      <inertial pos="0 0.01634 -0.0018" quat="0.5 0.5 -0.5 0.5" mass="1.219" diaginertia="0.0021942 0.00183104 0.00183104" />
                      <joint name="la_wrist_2_joint" class="ur5" pos="0 0 0" axis="0 0 1" actuatorfrcrange="-28 28" />
                      <geom class="visual" pos="0 0 -0.095" quat="1 0 0 0" type="mesh" material="gray" mesh="wrist2" />
                      <geom name="la_wrist_2_link_geom_1" class="collision" size="0.04 0.035" pos="0 0.01 0" quat="0.707107 0.707107 0 0" type="capsule" rgba="1 0 0 1" />
                      <geom name="la_wrist_2_link_geom_0" class="collision" size="0.04 0.06" pos="0 0 -0.06" type="capsule" rgba="1 0 0 1" />
                      <body name="la_wrist_3_link" pos="0 0.0823 -1.688e-11" quat="0.707107 -0.707107 0 0" gravcomp="1">
                        <inertial pos="0 0 -0.001159" quat="0.5 0.5 -0.5 0.5" mass="0.1879" diaginertia="0.000132117 8.06248e-05 8.06248e-05" />
                        <joint name="la_wrist_3_joint" class="ur5" pos="0 0 0" axis="0 0 1" actuatorfrcrange="-28 28" />
                        <geom class="visual" pos="0 0 -0.0818" quat="0.707107 0.707107 0 0" type="mesh" material="gray" mesh="wrist3" />
                        <body name="la_ft_frame" quat="0 1 0 0" gravcomp="1" />
                        <body name="la_flange" quat="0.5 -0.5 -0.5 -0.5" gravcomp="1">
                          <body name="la_tool0" quat="0.5 0.5 0.5 0.5" gravcomp="1">
                            <body name="lh_palm" pos="0 0 0.034" gravcomp="1">
                              <inertial pos="0 0 0.035" quat="0.707107 0 0 0.707107" mass="0.3" diaginertia="0.0005287 0.0003581 0.000191" />
                              <geom class="lh_plastic_visual" mesh="lh_palm" />
                              <geom class="lh_plastic_collision" size="0.031 0.0035 0.049" pos="-0.011 0.0085 0.038" type="box" />
                              <geom class="lh_plastic_collision" size="0.018 0.0085 0.049" pos="0.002 -0.0035 0.038" type="box" />
                              <geom class="lh_plastic_collision" size="0.013 0.0085 0.005" pos="-0.029 -0.0035 0.082" type="box" />
                              <geom class="lh_plastic_collision" size="0.013 0.007 0.009" pos="-0.0265 -0.001 0.07" quat="0.987241 0.0990545 0.0124467 -0.124052" type="box" />
                              <geom class="lh_plastic_collision" size="0.0105 0.0135 0.0112" pos="-0.0315 -0.0085 0.001" type="box" />
                              <geom class="lh_plastic_collision" size="0.011 0.0025 0.015" pos="-0.0125 -0.015 0.004" quat="-0.971338 0 0 -0.237703" type="box" />
                              <geom class="lh_plastic_collision" size="0.009 0.012 0.002" pos="-0.011 0 0.089" type="box" />
                              <geom class="lh_plastic_collision" size="0.01 0.012 0.02" pos="0.03 0 0.009" type="box" />
                              <body name="lh_ffknuckle" pos="-0.033 0 0.095" gravcomp="1">
                                <inertial pos="0 0 0" quat="0.5 0.5 -0.5 0.5" mass="0.008" diaginertia="3.2e-07 2.6e-07 2.6e-07" />
                                <joint name="lh_FFJ4" class="lh_knuckle" pos="0 0 0" axis="0 1 0" />
                                <geom class="lh_plastic_visual" pos="0 0 0.0005" material="metallic" mesh="lh_f_knuckle" />
                                <body name="lh_ffproximal" gravcomp="1">
                                  <inertial pos="0 0 0.0225" quat="0.707107 0 0 0.707107" mass="0.03" diaginertia="1e-05 9.8e-06 1.8e-06" />
                                  <joint name="lh_FFJ3" class="lh_proximal" pos="0 0 0" axis="1 0 0" />
                                  <geom class="lh_plastic_visual" mesh="lh_f_proximal" />
                                  <geom class="lh_plastic_collision" size="0.009 0.02" pos="0 0 0.025" type="capsule" />
                                  <body name="lh_ffmiddle" pos="0 0 0.045" gravcomp="1">
                                    <inertial pos="0 0 0.0125" quat="0.707107 0 0 0.707107" mass="0.017" diaginertia="2.7e-06 2.6e-06 8.7e-07" />
                                    <joint name="lh_FFJ2" class="lh_middle_distal" pos="0 0 0" axis="1 0 0" />
                                    <geom class="lh_plastic_visual" mesh="lh_f_middle" />
                                    <geom class="lh_plastic_collision" size="0.009 0.0125" pos="0 0 0.0125" type="capsule" />
                                    <body name="lh_ffdistal" pos="0 0 0.025" gravcomp="1">
                                      <inertial pos="0 0 0.0130769" quat="0.707107 0 0 0.707107" mass="0.013" diaginertia="1.28092e-06 1.12092e-06 5.3e-07" />
                                      <joint name="lh_FFJ1" class="lh_middle_distal" pos="0 0 0" axis="1 0 0" />
                                      <geom class="lh_plastic_visual" mesh="lh_f_distal" />
                                      <geom class="lh_plastic_collision" type="mesh" mesh="lh_f_distal" />
                                    </body>
                                  </body>
                                </body>
                              </body>
                              <body name="lh_mfknuckle" pos="-0.011 0 0.099" gravcomp="1">
                                <inertial pos="0 0 0" quat="0.5 0.5 -0.5 0.5" mass="0.008" diaginertia="3.2e-07 2.6e-07 2.6e-07" />
                                <joint name="lh_MFJ4" class="lh_knuckle" pos="0 0 0" axis="0 1 0" />
                                <geom class="lh_plastic_visual" pos="0 0 0.0005" material="metallic" mesh="lh_f_knuckle" />
                                <body name="lh_mfproximal" gravcomp="1">
                                  <inertial pos="0 0 0.0225" quat="0.707107 0 0 0.707107" mass="0.03" diaginertia="1e-05 9.8e-06 1.8e-06" />
                                  <joint name="lh_MFJ3" class="lh_proximal" pos="0 0 0" axis="1 0 0" />
                                  <geom class="lh_plastic_visual" mesh="lh_f_proximal" />
                                  <geom class="lh_plastic_collision" size="0.009 0.02" pos="0 0 0.025" type="capsule" />
                                  <body name="lh_mfmiddle" pos="0 0 0.045" gravcomp="1">
                                    <inertial pos="0 0 0.0125" quat="0.707107 0 0 0.707107" mass="0.017" diaginertia="2.7e-06 2.6e-06 8.7e-07" />
                                    <joint name="lh_MFJ2" class="lh_middle_distal" pos="0 0 0" axis="1 0 0" />
                                    <geom class="lh_plastic_visual" mesh="lh_f_middle" />
                                    <geom class="lh_plastic_collision" size="0.009 0.0125" pos="0 0 0.0125" type="capsule" />
                                    <body name="lh_mfdistal" pos="0 0 0.025" gravcomp="1">
                                      <inertial pos="0 0 0.0130769" quat="0.707107 0 0 0.707107" mass="0.013" diaginertia="1.28092e-06 1.12092e-06 5.3e-07" />
                                      <joint name="lh_MFJ1" class="lh_middle_distal" pos="0 0 0" axis="1 0 0" />
                                      <geom class="lh_plastic_visual" mesh="lh_f_distal" />
                                      <geom class="lh_plastic_collision" type="mesh" mesh="lh_f_distal" />
                                    </body>
                                  </body>
                                </body>
                              </body>
                              <body name="lh_rfknuckle" pos="0.011 0 0.095" gravcomp="1">
                                <inertial pos="0 0 0" quat="0.5 0.5 -0.5 0.5" mass="0.008" diaginertia="3.2e-07 2.6e-07 2.6e-07" />
                                <joint name="lh_RFJ4" class="lh_knuckle" pos="0 0 0" axis="0 -1 0" />
                                <geom class="lh_plastic_visual" pos="0 0 0.0005" material="metallic" mesh="lh_f_knuckle" />
                                <body name="lh_rfproximal" gravcomp="1">
                                  <inertial pos="0 0 0.0225" quat="0.707107 0 0 0.707107" mass="0.03" diaginertia="1e-05 9.8e-06 1.8e-06" />
                                  <joint name="lh_RFJ3" class="lh_proximal" pos="0 0 0" axis="1 0 0" />
                                  <geom class="lh_plastic_visual" mesh="lh_f_proximal" />
                                  <geom class="lh_plastic_collision" size="0.009 0.02" pos="0 0 0.025" type="capsule" />
                                  <body name="lh_rfmiddle" pos="0 0 0.045" gravcomp="1">
                                    <inertial pos="0 0 0.0125" quat="0.707107 0 0 0.707107" mass="0.017" diaginertia="2.7e-06 2.6e-06 8.7e-07" />
                                    <joint name="lh_RFJ2" class="lh_middle_distal" pos="0 0 0" axis="1 0 0" />
                                    <geom class="lh_plastic_visual" mesh="lh_f_middle" />
                                    <geom class="lh_plastic_collision" size="0.009 0.0125" pos="0 0 0.0125" type="capsule" />
                                    <body name="lh_rfdistal" pos="0 0 0.025" gravcomp="1">
                                      <inertial pos="0 0 0.0130769" quat="0.707107 0 0 0.707107" mass="0.013" diaginertia="1.28092e-06 1.12092e-06 5.3e-07" />
                                      <joint name="lh_RFJ1" class="lh_middle_distal" pos="0 0 0" axis="1 0 0" />
                                      <geom class="lh_plastic_visual" mesh="lh_f_distal" />
                                      <geom class="lh_plastic_collision" type="mesh" mesh="lh_f_distal" />
                                    </body>
                                  </body>
                                </body>
                              </body>
                              <body name="lh_lfmetacarpal" pos="0.033 0 0.02071" gravcomp="1">
                                <inertial pos="0 0 0.04" quat="0.707107 0 0 0.707107" mass="0.03" diaginertia="1.638e-05 1.45e-05 4.272e-06" />
                                <joint name="lh_LFJ5" class="lh_metacarpal" pos="0 0 0" axis="0.573576 0 -0.819152" />
                                <geom class="lh_plastic_visual" mesh="lh_lf_metacarpal" />
                                <geom class="lh_plastic_collision" size="0.011 0.012 0.025" pos="-0.002 0 0.033" type="box" />
                                <body name="lh_lfknuckle" pos="0 0 0.06579" gravcomp="1">
                                  <inertial pos="0 0 0" quat="0.5 0.5 -0.5 0.5" mass="0.008" diaginertia="3.2e-07 2.6e-07 2.6e-07" />
                                  <joint name="lh_LFJ4" class="lh_knuckle" pos="0 0 0" axis="0 -1 0" />
                                  <geom class="lh_plastic_visual" pos="0 0 0.0005" material="metallic" mesh="lh_f_knuckle" />
                                  <body name="lh_lfproximal" gravcomp="1">
                                    <inertial pos="0 0 0.0225" quat="0.707107 0 0 0.707107" mass="0.03" diaginertia="1e-05 9.8e-06 1.8e-06" />
                                    <joint name="lh_LFJ3" class="lh_proximal" pos="0 0 0" axis="1 0 0" />
                                    <geom class="lh_plastic_visual" mesh="lh_f_proximal" />
                                    <geom class="lh_plastic_collision" size="0.009 0.02" pos="0 0 0.025" type="capsule" />
                                    <body name="lh_lfmiddle" pos="0 0 0.045" gravcomp="1">
                                      <inertial pos="0 0 0.0125" quat="0.707107 0 0 0.707107" mass="0.017" diaginertia="2.7e-06 2.6e-06 8.7e-07" />
                                      <joint name="lh_LFJ2" class="lh_middle_distal" pos="0 0 0" axis="1 0 0" />
                                      <geom class="lh_plastic_visual" mesh="lh_f_middle" />
                                      <geom class="lh_plastic_collision" size="0.009 0.0125" pos="0 0 0.0125" type="capsule" />
                                      <body name="lh_lfdistal" pos="0 0 0.025" gravcomp="1">
                                        <inertial pos="0 0 0.0130769" quat="0.707107 0 0 0.707107" mass="0.013" diaginertia="1.28092e-06 1.12092e-06 5.3e-07" />
                                        <joint name="lh_LFJ1" class="lh_middle_distal" pos="0 0 0" axis="1 0 0" />
                                        <geom class="lh_plastic_visual" mesh="lh_f_distal" />
                                        <geom class="lh_plastic_collision" type="mesh" mesh="lh_f_distal" />
                                      </body>
                                    </body>
                                  </body>
                                </body>
                              </body>
                              <body name="lh_thbase" pos="-0.034 -0.00858 0.029" quat="0 -0.382683 0 0.92388" gravcomp="1">
                                <inertial pos="0 0 0" mass="0.01" diaginertia="1.6e-07 1.6e-07 1.6e-07" />
                                <joint name="lh_THJ5" class="lh_thbase" pos="0 0 0" axis="0 0 1" />
                                <geom class="lh_plastic_collision" size="0.013" />
                                <body name="lh_thproximal" gravcomp="1">
                                  <inertial pos="0 0 0.019" mass="0.04" diaginertia="1.36e-05 1.36e-05 3.13e-06" />
                                  <joint name="lh_THJ4" class="lh_thproximal" pos="0 0 0" axis="-1 0 0" />
                                  <geom class="lh_plastic_visual" mesh="lh_th_proximal" />
                                  <geom class="lh_plastic_collision" size="0.0105 0.009" pos="0 0 0.02" type="capsule" />
                                  <body name="lh_thhub" pos="0 0 0.038" gravcomp="1">
                                    <inertial pos="0 0 0" mass="0.005" diaginertia="1e-06 1e-06 3e-07" />
                                    <joint name="lh_THJ3" class="lh_thhub" pos="0 0 0" axis="-1 0 0" />
                                    <geom class="lh_plastic_collision" size="0.011" />
                                    <body name="lh_thmiddle" gravcomp="1">
                                      <inertial pos="0 0 0.016" mass="0.02" diaginertia="5.1e-06 5.1e-06 1.21e-06" />
                                      <joint name="lh_THJ2" class="lh_thmiddle" pos="0 0 0" axis="0 -1 0" />
                                      <geom class="lh_plastic_visual" mesh="lh_th_middle" />
                                      <geom class="lh_plastic_collision" size="0.009 0.009" pos="0 0 0.012" type="capsule" />
                                      <geom class="lh_plastic_collision" size="0.01" pos="0 0 0.03" />
                                      <body name="lh_thdistal" pos="0 0 0.032" quat="0.707107 0 0 -0.707107" gravcomp="1">
                                        <inertial pos="0 0 0.0145588" quat="0.707107 0 0 0.707107" mass="0.017" diaginertia="2.37794e-06 2.27794e-06 1e-06" />
                                        <joint name="lh_THJ1" class="lh_thdistal" pos="0 0 0" axis="1 0 0" />
                                        <geom class="lh_plastic_visual" mesh="lh_th_distal" />
                                        <geom class="lh_plastic_collision" type="mesh" mesh="lh_th_distal" />
                                      </body>
                                    </body>
                                  </body>
                                </body>
                              </body>
                            </body>
                          </body>
                        </body>
                      </body>
                    </body>
                  </body>
                </body>
              </body>
            </body>
          </body>
          <body name="la_base" quat="0 0 0 1" gravcomp="1" />
        </body>
      </body>
    </body>
  </worldbody>

  <contact>
    <exclude body1="dual_base" body2="ra_base_link_inertia" />
    <exclude body1="dual_base" body2="ra_shoulder_link" />
    <exclude body1="dual_base" body2="la_base_link_inertia" />
    <exclude body1="dual_base" body2="la_shoulder_link" />
    <exclude body1="ra_base_link_inertia" body2="ra_shoulder_link" />
    <exclude body1="rh_palm" body2="rh_ffknuckle" />
    <exclude body1="rh_palm" body2="rh_mfknuckle" />
    <exclude body1="rh_palm" body2="rh_rfknuckle" />
    <exclude body1="rh_palm" body2="rh_lfmetacarpal" />
    <exclude body1="rh_thproximal" body2="rh_thmiddle" />
    <exclude body1="la_base_link_inertia" body2="la_shoulder_link" />
    <exclude body1="lh_palm" body2="lh_ffknuckle" />
    <exclude body1="lh_palm" body2="lh_mfknuckle" />
    <exclude body1="lh_palm" body2="lh_rfknuckle" />
    <exclude body1="lh_palm" body2="lh_lfmetacarpal" />
    <exclude body1="lh_thproximal" body2="lh_thmiddle" />
  </contact>

  <actuator>
        <general class="size3" name="ra_actuator_0" joint="ra_shoulder_pan_joint" />
        <general class="size3" name="ra_actuator_1" joint="ra_shoulder_lift_joint" />
        <general class="size3_limited" name="ra_actuator_2" joint="ra_elbow_joint" />
        <general class="size1" name="ra_actuator_3" joint="ra_wrist_1_joint" />
        <general class="size1" name="ra_actuator_4" joint="ra_wrist_2_joint" />
        <general class="size1" name="ra_actuator_5" joint="ra_wrist_3_joint" />

        <general class="size3" name="la_actuator_0" joint="la_shoulder_pan_joint" />
        <general class="size3" name="la_actuator_1" joint="la_shoulder_lift_joint" />
        <general class="size3_limited" name="la_actuator_2" joint="la_elbow_joint" />
        <general class="size1" name="la_actuator_3" joint="la_wrist_1_joint" />
        <general class="size1" name="la_actuator_4" joint="la_wrist_2_joint" />
        <general class="size1" name="la_actuator_5" joint="la_wrist_3_joint" />

        <position name="rh_A_THJ5" joint="rh_THJ5" class="rh_thbase" />
        <position name="rh_A_THJ4" joint="rh_THJ4" class="rh_thproximal" />
        <position name="rh_A_THJ3" joint="rh_THJ3" class="rh_thhub" />
        <position name="rh_A_THJ2" joint="rh_THJ2" class="rh_thmiddle" />
        <position name="rh_A_THJ1" joint="rh_THJ1" class="rh_thdistal" />
        <position name="rh_A_FFJ4" joint="rh_FFJ4" class="rh_knuckle" />
        <position name="rh_A_FFJ3" joint="rh_FFJ3" class="rh_proximal" />
        <position name="rh_A_FFJ2" joint="rh_FFJ2" class="rh_middle_distal" />
        <position name="rh_A_FFJ1" joint="rh_FFJ1" class="rh_middle_distal" />
        <position name="rh_A_MFJ4" joint="rh_MFJ4" class="rh_knuckle" />
        <position name="rh_A_MFJ3" joint="rh_MFJ3" class="rh_proximal" />
        <position name="rh_A_MFJ2" joint="rh_MFJ2" class="rh_middle_distal" />
        <position name="rh_A_MFJ1" joint="rh_MFJ1" class="rh_middle_distal" />
        <position name="rh_A_RFJ4" joint="rh_RFJ4" class="rh_knuckle" />
        <position name="rh_A_RFJ3" joint="rh_RFJ3" class="rh_proximal" />
        <position name="rh_A_RFJ2" joint="rh_RFJ2" class="rh_middle_distal" />
        <position name="rh_A_RFJ1" joint="rh_RFJ1" class="rh_middle_distal" />
        <position name="rh_A_LFJ5" joint="rh_LFJ5" class="rh_metacarpal" />
        <position name="rh_A_LFJ4" joint="rh_LFJ4" class="rh_knuckle" />
        <position name="rh_A_LFJ3" joint="rh_LFJ3" class="rh_proximal" />
        <position name="rh_A_LFJ2" joint="rh_LFJ2" class="rh_middle_distal" />
        <position name="rh_A_LFJ1" joint="rh_LFJ1" class="rh_middle_distal" />

        <position name="lh_A_THJ5" joint="lh_THJ5" class="lh_thbase" />
        <position name="lh_A_THJ4" joint="lh_THJ4" class="lh_thproximal" />
        <position name="lh_A_THJ3" joint="lh_THJ3" class="lh_thhub" />
        <position name="lh_A_THJ2" joint="lh_THJ2" class="lh_thmiddle" />
        <position name="lh_A_THJ1" joint="lh_THJ1" class="lh_thdistal" />
        <position name="lh_A_FFJ4" joint="lh_FFJ4" class="lh_knuckle" />
        <position name="lh_A_FFJ3" joint="lh_FFJ3" class="lh_proximal" />
        <position name="lh_A_FFJ2" joint="lh_FFJ2" class="lh_middle_distal" />
        <position name="lh_A_FFJ1" joint="lh_FFJ1" class="lh_middle_distal" />
        <position name="lh_A_MFJ4" joint="lh_MFJ4" class="lh_knuckle" />
        <position name="lh_A_MFJ3" joint="lh_MFJ3" class="lh_proximal" />
        <position name="lh_A_MFJ2" joint="lh_MFJ2" class="lh_middle_distal" />
        <position name="lh_A_MFJ1" joint="lh_MFJ1" class="lh_middle_distal" />
        <position name="lh_A_RFJ4" joint="lh_RFJ4" class="lh_knuckle" />
        <position name="lh_A_RFJ3" joint="lh_RFJ3" class="lh_proximal" />
        <position name="lh_A_RFJ2" joint="lh_RFJ2" class="lh_middle_distal" />
        <position name="lh_A_RFJ1" joint="lh_RFJ1" class="lh_middle_distal" />
        <position name="lh_A_LFJ5" joint="lh_LFJ5" class="lh_metacarpal" />
        <position name="lh_A_LFJ4" joint="lh_LFJ4" class="lh_knuckle" />
        <position name="lh_A_LFJ3" joint="lh_LFJ3" class="lh_proximal" />
        <position name="lh_A_LFJ2" joint="lh_LFJ2" class="lh_middle_distal" />
        <position name="lh_A_LFJ1" joint="lh_LFJ1" class="lh_middle_distal" />

    </actuator>
<default>
        <joint damping="0.01" armature="0.01" />

        
        <default class="ur5">
            <material specular="0.5" shininess="0.25" />
            <joint axis="0 1 0" range="-6.28319 6.28319" armature="0.1" />
            <general gaintype="fixed" biastype="affine" ctrlrange="-6.2831 6.2831" gainprm="2000" biasprm="0 -2000 -400" forcerange="-150 150" />
            <default class="size3">
                <default class="size3_limited">
                    <joint range="-3.1415 3.1415" />
                    <general ctrlrange="-3.1415 3.1415" />
                </default>
            </default>
            <default class="size1">
                <general gainprm="500" biasprm="0 -500 -100" forcerange="-28 28" />
            </default>
            <default class="visual">
                <geom group="1" contype="0" conaffinity="0" density="0" material="black" />
            </default>
            <default class="collision">
                <geom group="3" />  
            </default>
        </default>

        <default class="right_hand">
            <mesh scale="0.001 0.001 0.001" />
            <joint axis="1 0 0" damping="0.05" armature="0.0002" frictionloss="0.01" />
            <position forcerange="-1 1" />

            <default class="rh_thumb">
                <default class="rh_thbase">
                    <joint axis="0 0 -1" range="-1.0472 1.0472" />
                    <position kp="0.4" ctrlrange="-1.0472 1.0472" forcerange="-3 3" />
                </default>
                <default class="rh_thproximal">
                    <joint range="0 1.22173" />
                    <position ctrlrange="0 1.22173" forcerange="-2 2" />
                </default>
                <default class="rh_thhub">
                    <joint range="-0.20944 0.20944" />
                    <position kp="0.5" ctrlrange="-0.20944 0.20944" />
                </default>
                <default class="rh_thmiddle">
                    <joint axis="0 -1 0" range="-0.698132 0.698132" />
                    <position kp="1.5" ctrlrange="-0.698132 0.698132" />
                </default>
                <default class="rh_thdistal">
                    <joint range="-0.261799 1.5708" />
                    <position ctrlrange="-0.261799 1.5708" />
                </default>
            </default>

            <default class="rh_metacarpal">
                <joint axis="0.573576 0 0.819152" range="0 0.785398" />
                <position ctrlrange="0 0.785398" />
            </default>
            <default class="rh_knuckle">
                <joint axis="0 -1 0" range="-0.349066 0.349066" />
                <position ctrlrange="-0.349066 0.349066" />
            </default>
            <default class="rh_proximal">
                <joint range="-0.261799 1.5708" />
                <position ctrlrange="-0.261799 1.5708" />
            </default>
            <default class="rh_middle_distal">
                <joint range="0 1.5708" />
                <position kp="0.5" ctrlrange="0 1.5708" />
            </default>

            <default class="rh_plastic">
                <geom solimp="0.5 0.99 0.0001" solref="0.005 1" />
                <default class="rh_plastic_visual">
                    <geom type="mesh" material="black" contype="0" conaffinity="0" group="2" />
                </default>
                <default class="rh_plastic_collision">
                    <geom group="3" />
                </default>
            </default>
        </default>

        <default class="left_hand">
            <mesh scale="0.001 0.001 0.001" />
            <joint axis="1 0 0" damping="0.05" armature="0.0002" frictionloss="0.01" />
            <position forcerange="-1 1" />

            <default class="lh_thumb">
                <default class="lh_thbase">
                    <joint axis="0 0 1" range="-1.0472 1.0472" />
                    <position kp="0.4" ctrlrange="-1.0472 1.0472" forcerange="-3 3" />
                </default>
                <default class="lh_thproximal">
                    <joint axis="-1 0 0" range="0 1.22173" />
                    <position ctrlrange="0 1.22173" forcerange="-2 2" />
                </default>
                <default class="lh_thhub">
                    <joint axis="-1 0 0" range="-0.20944 0.20944" />
                    <position kp="0.5" ctrlrange="-0.20944 0.20944" />
                </default>
                <default class="lh_thmiddle">
                    <joint axis="0 -1 0" range="-0.698132 0.698132" />
                    <position kp="1.5" ctrlrange="-0.698132 0.698132" />
                </default>
                <default class="lh_thdistal">
                    <joint range="-0.261799 1.5708" />
                    <position ctrlrange="-0.261799 1.5708" />
                </default>
            </default>

            <default class="lh_metacarpal">
                <joint axis="0.573576 0 0.819152" range="0 0.785398" />
                <position ctrlrange="0 0.785398" />
            </default>
            <default class="lh_knuckle">
                <joint axis="0 -1 0" range="-0.349066 0.349066" />
                <position ctrlrange="-0.349066 0.349066" />
            </default>
            <default class="lh_proximal">
                <joint range="-0.261799 1.5708" />
                <position ctrlrange="-0.261799 1.5708" />
            </default>
            <default class="lh_middle_distal">
                <joint range="0 1.5708" />
                <position kp="0.5" ctrlrange="0 3.1415" />
            </default>

            <default class="lh_plastic">
                <geom solimp="0.5 0.99 0.0001" solref="0.005 1" />
                <default class="lh_plastic_visual">
                    <geom type="mesh" material="black" contype="0" conaffinity="0" group="2" />
                </default>
                <default class="lh_plastic_collision">
                    <geom group="3" />
                </default>
            </default>
        </default>
    </default>

    </mujoco>